Workbook

Sheet Settings
C2: Power_W | F2: Machine
C3: Key Settings | F3: Machine | G3: Power_W | H3: Purchase_Price | I3: Life_hours | J3: Maintenance_pct
C4: Electricity_rate_per_kWh | D4: =812 -> 812 | F4: Anycubic Kobra S1- office | G4: 120 | H4: 94000000 | I4: 5000 | J4: 0.05
C5: Default_markup_pct | D5: 2 | F5: Anycubic Kobra S1- barbod | G5: 120 | H5: 75000000 | I5: 5000 | J5: 0.05
F6: Sunlu t3 | G6: 120 | H6: 23000000 | I6: 3000 | J6: 0.05
C11: Overhead (Material-based)
C12: Overhead_fixed_per_job | D12: 0.3
C13: Overhead_pct_on_material | D13: 0
C14: Overhead_rate_per_100g | D14: 0
C18: Coloring coast/h | D18: 150000

Sheet Materials
D5: Material | E5: Price_per_kg | F5: Waste_pct | G5: Color | H5: Notes
D6: PLA | E6: 2600000 | F6: 0.05 | G6: Black | H6: General purpose
D7: PLA | E7: 2600000 | F7: 0.05 | G7: orange | H7: General purpose
D8: PLA | E8: 2600000 | F8: 0.05 | G8: gray | H8: General purpose
D9: PLA | E9: 2600000 | F9: 0.05 | G9: Red | H9: General purpose
D10: PLA | E10: 2600000 | F10: 0.05 | G10: white | H10: General purpose
D11: PLA silk | E11: 2600000 | F11: 0.05 | G11: gold black | H11: General purpose
D12: PETG | E12: 3200000 | F12: 0.07 | G12: black | H12: Heat resistant
D13: TPU (95A) | E13: 2480000 | F13: 0.08 | G13: black | H13: Flexible
D14: PLA + | E14: 2600000 | F14: 0.05 | G14: Olive Green | H14: General purpose
D15: PLA + | E15: 2600000 | F15: 0.05 | G15: Pine Green | H15: General purpose
D16: PETG | E16: 3200000 | F16: 0.07 | G16: White | H16: General purpose
D17: PLA SILK | E17: 3300000 | F17: 0.05 | G17: Gold blue coper | H17: General purpose
... D23: PLA MATE | E23: 3300000 | F23: 0.05 | G23: lavander purple | H23: General purpose
D24: PLA Fast | E24: 3300000 | F24: 0.05 | G24: white
D25: petg transparent | E25: 3300000 | F25: 0.05 | G25: TRANSPARENT

Sheet Jobs
A1: Product ID | B1: Product | C1: Qty | D1: Machine | E1: Material | F1: color | G1: Wight/g | H1: Support/g | I1: Flushed/g | J1: Print/h | K1: Post Pro/h | L1: Extras | M1: Matrial/t | N1: power/t | O1: downturn/t | P1: Maintenance/t | Q1: Coloring/t | R1: overhead/t | S1: base price/t | T1: Sugested Price/t | U1: Gross margin/t | V1: margin %/t
B2: دویل گیرل اکسسوری | C2: 1 | D2: Anycubic Kobra S1- office | E2: PLA | F2: Red | G2: 13 | H2: 0 | I2: 0 | J2: 0.041666667 | K2: 0 | L2: 0 | M2: =_xlfn.LET( _xlpm.qty, C2, _xlpm.weight_g, G2 + H2 + Jobs[[#This Row],[Flushed/g]], _xlpm.material, TRIM(E2), _xlpm.price_per_kg, _xlfn.XLOOKUP(_xlpm.material, MaterialsTbl[Material], MaterialsTbl[Price_per_kg], 0), _xlpm.waste_pct, _xlfn.XLOOKUP(_xlpm.material, MaterialsTbl[Material], MaterialsTbl[Waste_pct], 0), _xlpm.qty * (_xlpm.weight_g / 1000) * _xlpm.price_per_kg * (1 + _xlpm.waste_pct) ) -> 35490 | N2: =_xlfn.LET( _xlpm.qty, C2, _xlpm.hours, J2*24, _xlpm.power_w, _xlfn.XLOOKUP(TRIM(D2), Settings!$F$4:$F$101, Settings!$G$4:$G$101, 120), _xlpm.rate, Settings!$D$4, _xlpm.qty * _xlpm.hours * (_xlpm.power_w / 1000) * _xlpm.rate ) -> 97.44 | O2: =_xlfn.LET( _xlpm.qty, C2, _xlpm.hours, J2*24, _xlpm.price, _xlfn.XLOOKUP(TRIM(D2), Settings!$F$4:$F$101, Settings!$H$4:$H$101, 0), _xlpm.life, _xlfn.XLOOKUP(TRIM(D2), Settings!$F$4:$F$101, Settings!$I$4:$I$101, 1), _xlpm.qty * _xlpm.hours * (_xlpm.price / _xlpm.life) ) -> 18800 | P2: =_xlfn.LET( _xlpm.qty, C2, _xlpm.hours, J2*24, _xlpm.price, _xlfn.XLOOKUP(TRIM(D2), Settings!$F$4:$F$101, Settings!$H$4:$H$101, 0), _xlpm.life, _xlfn.XLOOKUP(TRIM(D2), Settings!$F$4:$F$101, Settings!$I$4:$I$101, 1), _xlpm.pct, _xlfn.XLOOKUP(TRIM(D2), Settings!$F$4:$F$101, Settings!$J$4:$J$101, 0), _xlpm.qty * _xlpm.hours * (_xlpm.price / _xlpm.life * _xlpm.pct) ) -> 940 | Q2: =Jobs[[#This Row],[Post Pro/h]]*Settings!$D$18 -> 0 | R2: =(Jobs[[#This Row],[power/t]]+Jobs[[#This Row],[Matrial/t]]+Jobs[[#This Row],[downturn/t]]+Jobs[[#This Row],[Maintenance/t]]+Jobs[[#This Row],[Coloring/t]]+Jobs[[#This Row],[Extras]])*Settings!$D$12 -> 16598.232 | S2: =Jobs[[#This Row],[Matrial/t]] + Jobs[[#This Row],[power/t]] + Jobs[[#This Row],[downturn/t]] + Jobs[[#This Row],[Maintenance/t]] + Jobs[[#This Row],[Coloring/t]] + Jobs[[#This Row],[overhead/t]] + Jobs[[#This Row],[Extras]] -> 71925.672 | T2: =S2*(1+Settings!$D$5) -> 215777.02 | U2: =Jobs[[#This Row],[Sugested Price/t]] - Jobs[[#This Row],[base price/t]] -> 143851.34 | V2: =IFERROR(Jobs[[#This Row],[Gross margin/t]] / Jobs[[#This Row],[base price/t]], 0) -> 2
B3: گوشواره دینو اسکال | C3: 1 | D3: Anycubic Kobra S1- office | E3: PLA | F3: white | G3: 4.18 | H3: 2.82 | I3: 0 | J3: 0.041666667 | M3: =_xlfn.LET( _xlpm.qty, C3, _xlpm.weight_g, G3 + H3 + Jobs[[#This Row],[Flushed/g]], _xlpm.material, TRIM(E3), _xlpm.price_per_kg, _xlfn.XLOOKUP(_xlpm.material, MaterialsTbl[Material], MaterialsTbl[Price_per_kg], 0), _xlpm.waste_pct, _xlfn.XLOOKUP(_xlpm.material, MaterialsTbl[Material], MaterialsTbl[Waste_pct], 0), _xlpm.qty * (_xlpm.weight_g / 1000) * _xlpm.price_per_kg * (1 + _xlpm.waste_pct) ) -> 19110 | N3: =_xlfn.LET( _xlpm.qty, C3, _xlpm.hours, J3*24, _xlpm.power_w, _xlfn.XLOOKUP(TRIM(D3), Settings!$F$4:$F$101, Settings!$G$4:$G$101, 120), _xlpm.rate, Settings!$D$4, _xlpm.qty * _xlpm.hours * (_xlpm.power_w / 1000) * _xlpm.rate ) -> 97.44 | O3: =_xlfn.LET( _xlpm.qty, C3, _xlpm.hours, J3*24, _xlpm.price, _xlfn.XLOOKUP(TRIM(D3), Settings!$F$4:$F$101, Settings!$H$4:$H$101, 0), _xlpm.life, _xlfn.XLOOKUP(TRIM(D3), Settings!$F$4:$F$101, Settings!$I$4:$I$101, 1), _xlpm.qty * _xlpm.hours * (_xlpm.price / _xlpm.life) ) -> 18800 | P3: =_xlfn.LET( _xlpm.qty, C3, _xlpm.hours, J3*24, _xlpm.price, _xlfn.XLOOKUP(TRIM(D3), Settings!$F$4:$F$101, Settings!$H$4:$H$101, 0), _xlpm.life, _xlfn.XLOOKUP(TRIM(D3), Settings!$F$4:$F$101, Settings!$I$4:$I$101, 1), _xlpm.pct, _xlfn.XLOOKUP(TRIM(D3), Settings!$F$4:$F$101, Settings!$J$4:$J$101, 0), _xlpm.qty * _xlpm.hours * (_xlpm.price / _xlpm.life * _xlpm.pct) ) -> 940 | Q3: =Jobs[[#This Row],[Post Pro/h]]*Settings!$D$18 -> 0 | R3: =(Jobs[[#This Row],[power/t]]+Jobs[[#This Row],[Matrial/t]]+Jobs[[#This Row],[downturn/t]]+Jobs[[#This Row],[Maintenance/t]]+Jobs[[#This Row],[Coloring/t]]+Jobs[[#This Row],[Extras]])*Settings!$D$12 -> 11684.232 | S3: =Jobs[[#This Row],[Matrial/t]] + Jobs[[#This Row],[power/t]] + Jobs[[#This Row],[downturn/t]] + Jobs[[#This Row],[Maintenance/t]] + Jobs[[#This Row],[Coloring/t]] + Jobs[[#This Row],[overhead/t]] + Jobs[[#This Row],[Extras]] -> 50631.672 | T3: =S3*(1+Settings!$D$5) -> 151895.02 | U3: =Jobs[[#This Row],[Sugested Price/t]] - Jobs[[#This Row],[base price/t]] -> 101263.34 | V3: =IFERROR(Jobs[[#This Row],[Gross margin/t]] / Jobs[[#This Row],[base price/t]], 0) -> 2
B4: ست هیولا | C4: 1 | D4: Anycubic Kobra S1- office | E4: PLA | F4: Black | G4: 159 | H4: 0 | I4: 0 | J4: 0.25 | K4: 0 | M4: =_xlfn.LET( _xlpm.qty, C4, _xlpm.weight_g, G4 + H4 + Jobs[[#This Row],[Flushed/g]], _xlpm.material, TRIM(E4), _xlpm.price_per_kg, _xlfn.XLOOKUP(_xlpm.material, MaterialsTbl[Material], MaterialsTbl[Price_per_kg], 0), _xlpm.waste_pct, _xlfn.XLOOKUP(_xlpm.material, MaterialsTbl[Material], MaterialsTbl[Waste_pct], 0), _xlpm.qty * (_xlpm.weight_g / 1000) * _xlpm.price_per_kg * (1 + _xlpm.waste_pct) ) -> 434070 | N4: =_xlfn.LET( _xlpm.qty, C4, _xlpm.hours, J4*24, _xlpm.power_w, _xlfn.XLOOKUP(TRIM(D4), Settings!$F$4:$F$101, Settings!$G$4:$G$101, 120), _xlpm.rate, Settings!$D$4, _xlpm.qty * _xlpm.hours * (_xlpm.power_w / 1000) * _xlpm.rate ) -> 584.64 | O4: =_xlfn.LET( _xlpm.qty, C4, _xlpm.hours, J4*24, _xlpm.price, _xlfn.XLOOKUP(TRIM(D4), Settings!$F$4:$F$101, Settings!$H$4:$H$101, 0), _xlpm.life, _xlfn.XLOOKUP(TRIM(D4), Settings!$F$4:$F$101, Settings!$I$4:$I$101, 1), _xlpm.qty * _xlpm.hours * (_xlpm.price / _xlpm.life) ) -> 112800 | P4: =_xlfn.LET( _xlpm.qty, C4, _xlpm.hours, J4*24, _xlpm.price, _xlfn.XLOOKUP(TRIM(D4), Settings!$F$4:$F$101, Settings!$H$4:$H$101, 0), _xlpm.life, _xlfn.XLOOKUP(TRIM(D4), Settings!$F$4:$F$101, Settings!$I$4:$I$101, 1), _xlpm.pct, _xlfn.XLOOKUP(TRIM(D4), Settings!$F$4:$F$101, Settings!$J$4:$J$101, 0), _xlpm.qty * _xlpm.hours * (_xlpm.price / _xlpm.life * _xlpm.pct) ) -> 5640 | Q4: =Jobs[[#This Row],[Post Pro/h]]*Settings!$D$18 -> 0 | R4: =(Jobs[[#This Row],[power/t]]+Jobs[[#This Row],[Matrial/t]]+Jobs[[#This Row],[downturn/t]]+Jobs[[#This Row],[Maintenance/t]]+Jobs[[#This Row],[Coloring/t]]+Jobs[[#This Row],[Extras]])*Settings!$D$12 -> 165928.39 | S4: =Jobs[[#This Row],[Matrial/t]] + Jobs[[#This Row],[power/t]] + Jobs[[#This Row],[downturn/t]] + Jobs[[#This Row],[Maintenance/t]] + Jobs[[#This Row],[Coloring/t]] + Jobs[[#This Row],[overhead/t]] + Jobs[[#This Row],[Extras]] -> 719023.03 | T4: =S4*(1+Settings!$D$5) -> 2157069.1 | U4: =Jobs[[#This Row],[Sugested Price/t]] - Jobs[[#This Row],[base price/t]] -> 1438046.1 | V4: =IFERROR(Jobs[[#This Row],[Gross margin/t]] / Jobs[[#This Row],[base price/t]], 0) -> 2
B5: جای سیم حروف | C5: 1 | D5: Anycubic Kobra S1- office | E5: PLA | F5: Black | G5: 32 | H5: 0 | I5: 0 | J5: 0.083333333 | M5: =_xlfn.LET( _xlpm.qty, C5, _xlpm.weight_g, G5 + H5 + Jobs[[#This Row],[Flushed/g]], _xlpm.material, TRIM(E5), _xlpm.price_per_kg, _xlfn.XLOOKUP(_xlpm.material, MaterialsTbl[Material], MaterialsTbl[Price_per_kg], 0), _xlpm.waste_pct, _xlfn.XLOOKUP(_xlpm.material, MaterialsTbl[Material], MaterialsTbl[Waste_pct], 0), _xlpm.qty * (_xlpm.weight_g / 1000) * _xlpm.price_per_kg * (1 + _xlpm.waste_pct) ) -> 87360 | N5: =_xlfn.LET( _xlpm.qty, C5, _xlpm.hours, J5*24, _xlpm.power_w, _xlfn.XLOOKUP(TRIM(D5), Settings!$F$4:$F$101, Settings!$G$4:$G$101, 120), _xlpm.rate, Settings!$D$4, _xlpm.qty * _xlpm.hours * (_xlpm.power_w / 1000) * _xlpm.rate ) -> 194.88 | O5: =_xlfn.LET( _xlpm.qty, C5, _xlpm.hours, J5*24, _xlpm.price, _xlfn.XLOOKUP(TRIM(D5), Settings!$F$4:$F$101, Settings!$H$4:$H$101, 0), _xlpm.life, _xlfn.XLOOKUP(TRIM(D5), Settings!$F$4:$F$101, Settings!$I$4:$I$101, 1), _xlpm.qty * _xlpm.hours * (_xlpm.price / _xlpm.life) ) -> 37600 | P5: =_xlfn.LET( _xlpm.qty, C5, _xlpm.hours, J5*24, _xlpm.price, _xlfn.XLOOKUP(TRIM(D5), Settings!$F$4:$F$101, Settings!$H$4:$H$101, 0), _xlpm.life, _xlfn.XLOOKUP(TRIM(D5), Settings!$F$4:$F$101, Settings!$I$4:$I$101, 1), _xlpm.pct, _xlfn.XLOOKUP(TRIM(D5), Settings!$F$4:$F$101, Settings!$J$4:$J$101, 0), _xlpm.qty * _xlpm.hours * (_xlpm.price / _xlpm.life * _xlpm.pct) ) -> 1880 | Q5: =Jobs[[#This Row],[Post Pro/h]]*Settings!$D$18 -> 0 | R5: =(Jobs[[#This Row],[power/t]]+Jobs[[#This Row],[Matrial/t]]+Jobs[[#This Row],[downturn/t]]+Jobs[[#This Row],[Maintenance/t]]+Jobs[[#This Row],[Coloring/t]]+Jobs[[#This Row],[Extras]])*Settings!$D$12 -> 38110.464 | S5: =Jobs[[#This Row],[Matrial/t]] + Jobs[[#This Row],[power/t]] + Jobs[[#This Row],[downturn/t]] + Jobs[[#This Row],[Maintenance/t]] + Jobs[[#This Row],[Coloring/t]] + Jobs[[#This Row],[overhead/t]] + Jobs[[#This Row],[Extras]] -> 165145.34 | T5: =S5*(1+Settings!$D$5) -> 495436.03 | U5: =Jobs[[#This Row],[Sugested Price/t]] - Jobs[[#This Row],[base price/t]] -> 330290.69 | V5: =IFERROR(Jobs[[#This Row],[Gross margin/t]] / Jobs[[#This Row],[base price/t]], 0) -> 2
B6: گوشواره گل | C6: 1 | D6: Anycubic Kobra S1- office | E6: PLA | F6: white | G6: 3 | H6: 0 | I6: 0 | J6: 0.03125 | M6: =_xlfn.LET( _xlpm.qty, C6, _xlpm.weight_g, G6 + H6 + Jobs[[#This Row],[Flushed/g]], _xlpm.material, TRIM(E6), _xlpm.price_per_kg, _xlfn.XLOOKUP(_xlpm.material, MaterialsTbl[Material], MaterialsTbl[Price_per_kg], 0), _xlpm.waste_pct, _xlfn.XLOOKUP(_xlpm.material, MaterialsTbl[Material], MaterialsTbl[Waste_pct], 0), _xlpm.qty * (_xlpm.weight_g / 1000) * _xlpm.price_per_kg * (1 + _xlpm.waste_pct) ) -> 8190 | N6: =_xlfn.LET( _xlpm.qty, C6, _xlpm.hours, J6*24, _xlpm.power_w, _xlfn.XLOOKUP(TRIM(D6), Settings!$F$4:$F$101, Settings!$G$4:$G$101, 120), _xlpm.rate, Settings!$D$4, _xlpm.qty * _xlpm.hours * (_xlpm.power_w / 1000) * _xlpm.rate ) -> 73.08 | O6: =_xlfn.LET( _xlpm.qty, C6, _xlpm.hours, J6*24, _xlpm.price, _xlfn.XLOOKUP(TRIM(D6), Settings!$F$4:$F$101, Settings!$H$4:$H$101, 0), _xlpm.life, _xlfn.XLOOKUP(TRIM(D6), Settings!$F$4:$F$101, Settings!$I$4:$I$101, 1), _xlpm.qty * _xlpm.hours * (_xlpm.price / _xlpm.life) ) -> 14100 | P6: =_xlfn.LET( _xlpm.qty, C6, _xlpm.hours, J6*24, _xlpm.price, _xlfn.XLOOKUP(TRIM(D6), Settings!$F$4:$F$101, Settings!$H$4:$H$101, 0), _xlpm.life, _xlfn.XLOOKUP(TRIM(D6), Settings!$F$4:$F$101, Settings!$I$4:$I$101, 1), _xlpm.pct, _xlfn.XLOOKUP(TRIM(D6), Settings!$F$4:$F$101, Settings!$J$4:$J$101, 0), _xlpm.qty * _xlpm.hours * (_xlpm.price / _xlpm.life * _xlpm.pct) ) -> 705 | Q6: =Jobs[[#This Row],[Post Pro/h]]*Settings!$D$18 -> 0 | R6: =(Jobs[[#This Row],[power/t]]+Jobs[[#This Row],[Matrial/t]]+Jobs[[#This Row],[downturn/t]]+Jobs[[#This Row],[Maintenance/t]]+Jobs[[#This Row],[Coloring/t]]+Jobs[[#This Row],[Extras]])*Settings!$D$12 -> 6920.424 | S6: =Jobs[[#This Row],[Matrial/t]] + Jobs[[#This Row],[power/t]] + Jobs[[#This Row],[downturn/t]] + Jobs[[#This Row],[Maintenance/t]] + Jobs[[#This Row],[Coloring/t]] + Jobs[[#This Row],[overhead/t]] + Jobs[[#This Row],[Extras]] -> 29988.504 | T6: =S6*(1+Settings!$D$5) -> 89965.512 | U6: =Jobs[[#This Row],[Sugested Price/t]] - Jobs[[#This Row],[base price/t]] -> 59977.008 | V6: =IFERROR(Jobs[[#This Row],[Gross margin/t]] / Jobs[[#This Row],[base price/t]], 0) -> 2
B7: وان پیس | C7: 1 | D7: Anycubic Kobra S1- office | E7: PLA | F7: Black | G7: 21 | H7: 0 | I7: 0 | J7: 0.072916667 | M7: =_xlfn.LET( _xlpm.qty, C7, _xlpm.weight_g, G7 + H7 + Jobs[[#This Row],[Flushed/g]], _xlpm.material, TRIM(E7), _xlpm.price_per_kg, _xlfn.XLOOKUP(_xlpm.material, MaterialsTbl[Material], MaterialsTbl[Price_per_kg], 0), _xlpm.waste_pct, _xlfn.XLOOKUP(_xlpm.material, MaterialsTbl[Material], MaterialsTbl[Waste_pct], 0), _xlpm.qty * (_xlpm.weight_g / 1000) * _xlpm.price_per_kg * (1 + _xlpm.waste_pct) ) -> 57330 | N7: =_xlfn.LET( _xlpm.qty, C7, _xlpm.hours, J7*24, _xlpm.power_w, _xlfn.XLOOKUP(TRIM(D7), Settings!$F$4:$F$101, Settings!$G$4:$G$101, 120), _xlpm.rate, Settings!$D$4, _xlpm.qty * _xlpm.hours * (_xlpm.power_w / 1000) * _xlpm.rate ) -> 170.52 | O7: =_xlfn.LET( _xlpm.qty, C7, _xlpm.hours, J7*24, _xlpm.price, _xlfn.XLOOKUP(TRIM(D7), Settings!$F$4:$F$101, Settings!$H$4:$H$101, 0), _xlpm.life, _xlfn.XLOOKUP(TRIM(D7), Settings!$F$4:$F$101, Settings!$I$4:$I$101, 1), _xlpm.qty * _xlpm.hours * (_xlpm.price / _xlpm.life) ) -> 32900 | P7: =_xlfn.LET( _xlpm.qty, C7, _xlpm.hours, J7*24, _xlpm.price, _xlfn.XLOOKUP(TRIM(D7), Settings!$F$4:$F$101, Settings!$H$4:$H$101, 0), _xlpm.life, _xlfn.XLOOKUP(TRIM(D7), Settings!$F$4:$F$101, Settings!$I$4:$I$101, 1), _xlpm.pct, _xlfn.XLOOKUP(TRIM(D7), Settings!$F$4:$F$101, Settings!$J$4:$J$101, 0), _xlpm.qty * _xlpm.hours * (_xlpm.price / _xlpm.life * _xlpm.pct) ) -> 1645 | Q7: =Jobs[[#This Row],[Post Pro/h]]*Settings!$D$18 -> 0 | R7: =(Jobs[[#This Row],[power/t]]+Jobs[[#This Row],[Matrial/t]]+Jobs[[#This Row],[downturn/t]]+Jobs[[#This Row],[Maintenance/t]]+Jobs[[#This Row],[Coloring/t]]+Jobs[[#This Row],[Extras]])*Settings!$D$12 -> 27613.656 | S7: =Jobs[[#This Row],[Matrial/t]] + Jobs[[#This Row],[power/t]] + Jobs[[#This Row],[downturn/t]] + Jobs[[#This Row],[Maintenance/t]] + Jobs[[#This Row],[Coloring/t]] + Jobs[[#This Row],[overhead/t]] + Jobs[[#This Row],[Extras]] -> 119659.18 | T7: =S7*(1+Settings!$D$5) -> 358977.53 | U7: =Jobs[[#This Row],[Sugested Price/t]] - Jobs[[#This Row],[base price/t]] -> 239318.35 | V7: =IFERROR(Jobs[[#This Row],[Gross margin/t]] / Jobs[[#This Row],[base price/t]], 0) -> 2
B8: شونه موهای فر | C8: 1 | D8: Anycubic Kobra S1- office | E8: PETG | F8: Black | G8: 28 | H8: 0 | I8: 0 | J8: 0.0625 | M8: =_xlfn.LET( _xlpm.qty, C8, _xlpm.weight_g, G8 + H8 + Jobs[[#This Row],[Flushed/g]], _xlpm.material, TRIM(E8), _xlpm.price_per_kg, _xlfn.XLOOKUP(_xlpm.material, MaterialsTbl[Material], MaterialsTbl[Price_per_kg], 0), _xlpm.waste_pct, _xlfn.XLOOKUP(_xlpm.material, MaterialsTbl[Material], MaterialsTbl[Waste_pct], 0), _xlpm.qty * (_xlpm.weight_g / 1000) * _xlpm.price_per_kg * (1 + _xlpm.waste_pct) ) -> 95872 | N8: =_xlfn.LET( _xlpm.qty, C8, _xlpm.hours, J8*24, _xlpm.power_w, _xlfn.XLOOKUP(TRIM(D8), Settings!$F$4:$F$101, Settings!$G$4:$G$101, 120), _xlpm.rate, Settings!$D$4, _xlpm.qty * _xlpm.hours * (_xlpm.power_w / 1000) * _xlpm.rate ) -> 146.16 | O8: =_xlfn.LET( _xlpm.qty, C8, _xlpm.hours, J8*24, _xlpm.price, _xlfn.XLOOKUP(TRIM(D8), Settings!$F$4:$F$101, Settings!$H$4:$H$101, 0), _xlpm.life, _xlfn.XLOOKUP(TRIM(D8), Settings!$F$4:$F$101, Settings!$I$4:$I$101, 1), _xlpm.qty * _xlpm.hours * (_xlpm.price / _xlpm.life) ) -> 28200 | P8: =_xlfn.LET( _xlpm.qty, C8, _xlpm.hours, J8*24, _xlpm.price, _xlfn.XLOOKUP(TRIM(D8), Settings!$F$4:$F$101, Settings!$H$4:$H$101, 0), _xlpm.life, _xlfn.XLOOKUP(TRIM(D8), Settings!$F$4:$F$101, Settings!$I$4:$I$101, 1), _xlpm.pct, _xlfn.XLOOKUP(TRIM(D8), Settings!$F$4:$F$101, Settings!$J$4:$J$101, 0), _xlpm.qty * _xlpm.hours * (_xlpm.price / _xlpm.life * _xlpm.pct) ) -> 1410 | Q8: =Jobs[[#This Row],[Post Pro/h]]*Settings!$D$18 -> 0 | R8: =(Jobs[[#This Row],[power/t]]+Jobs[[#This Row],[Matrial/t]]+Jobs[[#This Row],[downturn/t]]+Jobs[[#This Row],[Maintenance/t]]+Jobs[[#This Row],[Coloring/t]]+Jobs[[#This Row],[Extras]])*Settings!$D$12 -> 37688.448 | S8: =Jobs[[#This Row],[Matrial/t]] + Jobs[[#This Row],[power/t]] + Jobs[[#This Row],[downturn/t]] + Jobs[[#This Row],[Maintenance/t]] + Jobs[[#This Row],[Coloring/t]] + Jobs[[#This Row],[overhead/t]] + Jobs[[#This Row],[Extras]] -> 163316.61 | T8: =S8*(1+Settings!$D$5) -> 489949.82 | U8: =Jobs[[#This Row],[Sugested Price/t]] - Jobs[[#This Row],[base price/t]] -> 326633.22 | V8: =IFERROR(Jobs[[#This Row],[Gross margin/t]] / Jobs[[#This Row],[base price/t]], 0) -> 2
B9: چای رژ لب | C9: 1 | D9: Anycubic Kobra S1- office | E9: PLA | F9: Red | G9: 23 | H9: 0 | I9: 0 | J9: 0.076388889 | M9: =_xlfn.LET( _xlpm.qty, C9, _xlpm.weight_g, G9 + H9 + Jobs[[#This Row],[Flushed/g]], _xlpm.material, TRIM(E9), _xlpm.price_per_kg, _xlfn.XLOOKUP(_xlpm.material, MaterialsTbl[Material], MaterialsTbl[Price_per_kg], 0), _xlpm.waste_pct, _xlfn.XLOOKUP(_xlpm.material, MaterialsTbl[Material], MaterialsTbl[Waste_pct], 0), _xlpm.qty * (_xlpm.weight_g / 1000) * _xlpm.price_per_kg * (1 + _xlpm.waste_pct) ) -> 62790 | N9: =_xlfn.LET( _xlpm.qty, C9, _xlpm.hours, J9*24, _xlpm.power_w, _xlfn.XLOOKUP(TRIM(D9), Settings!$F$4:$F$101, Settings!$G$4:$G$101, 120), _xlpm.rate, Settings!$D$4, _xlpm.qty * _xlpm.hours * (_xlpm.power_w / 1000) * _xlpm.rate ) -> 178.64 | O9: =_xlfn.LET( _xlpm.qty, C9, _xlpm.hours, J9*24, _xlpm.price, _xlfn.XLOOKUP(TRIM(D9), Settings!$F$4:$F$101, Settings!$H$4:$H$101, 0), _xlpm.life, _xlfn.XLOOKUP(TRIM(D9), Settings!$F$4:$F$101, Settings!$I$4:$I$101, 1), _xlpm.qty * _xlpm.hours * (_xlpm.price / _xlpm.life) ) -> 34466.667 | P9: =_xlfn.LET( _xlpm.qty, C9, _xlpm.hours, J9*24, _xlpm.price, _xlfn.XLOOKUP(TRIM(D9), Settings!$F$4:$F$101, Settings!$H$4:$H$101, 0), _xlpm.life, _xlfn.XLOOKUP(TRIM(D9), Settings!$F$4:$F$101, Settings!$I$4:$I$101, 1), _xlpm.pct, _xlfn.XLOOKUP(TRIM(D9), Settings!$F$4:$F$101, Settings!$J$4:$J$101, 0), _xlpm.qty * _xlpm.hours * (_xlpm.price / _xlpm.life * _xlpm.pct) ) -> 1723.3333 | Q9: =Jobs[[#This Row],[Post Pro/h]]*Settings!$D$18 -> 0 | R9: =(Jobs[[#This Row],[power/t]]+Jobs[[#This Row],[Matrial/t]]+Jobs[[#This Row],[downturn/t]]+Jobs[[#This Row],[Maintenance/t]]+Jobs[[#This Row],[Coloring/t]]+Jobs[[#This Row],[Extras]])*Settings!$D$12 -> 29747.592 | S9: =Jobs[[#This Row],[Matrial/t]] + Jobs[[#This Row],[power/t]] + Jobs[[#This Row],[downturn/t]] + Jobs[[#This Row],[Maintenance/t]] + Jobs[[#This Row],[Coloring/t]] + Jobs[[#This Row],[overhead/t]] + Jobs[[#This Row],[Extras]] -> 128906.23 | T9: =S9*(1+Settings!$D$5) -> 386718.7 | U9: =Jobs[[#This Row],[Sugested Price/t]] - Jobs[[#This Row],[base price/t]] -> 257812.46 | V9: =IFERROR(Jobs[[#This Row],[Gross margin/t]] / Jobs[[#This Row],[base price/t]], 0) -> 2
B10: فیدجت | C10: 1 | D10: Anycubic Kobra S1- office | E10: PLA | F10: Black | G10: 20 | H10: 0 | I10: 0 | J10: 0.041666667 | M10: =_xlfn.LET( _xlpm.qty, C10, _xlpm.weight_g, G10 + H10 + Jobs[[#This Row],[Flushed/g]], _xlpm.material, TRIM(E10), _xlpm.price_per_kg, _xlfn.XLOOKUP(_xlpm.material, MaterialsTbl[Material], MaterialsTbl[Price_per_kg], 0), _xlpm.waste_pct, _xlfn.XLOOKUP(_xlpm.material, MaterialsTbl[Material], MaterialsTbl[Waste_pct], 0), _xlpm.qty * (_xlpm.weight_g / 1000) * _xlpm.price_per_kg * (1 + _xlpm.waste_pct) ) -> 54600 | N10: =_xlfn.LET( _xlpm.qty, C10, _xlpm.hours, J10*24, _xlpm.power_w, _xlfn.XLOOKUP(TRIM(D10), Settings!$F$4:$F$101, Settings!$G$4:$G$101, 120), _xlpm.rate, Settings!$D$4, _xlpm.qty * _xlpm.hours * (_xlpm.power_w / 1000) * _xlpm.rate ) -> 97.44 | O10: =_xlfn.LET( _xlpm.qty, C10, _xlpm.hours, J10*24, _xlpm.price, _xlfn.XLOOKUP(TRIM(D10), Settings!$F$4:$F$101, Settings!$H$4:$H$101, 0), _xlpm.life, _xlfn.XLOOKUP(TRIM(D10), Settings!$F$4:$F$101, Settings!$I$4:$I$101, 1), _xlpm.qty * _xlpm.hours * (_xlpm.price / _xlpm.life) ) -> 18800 | P10: =_xlfn.LET( _xlpm.qty, C10, _xlpm.hours, J10*24, _xlpm.price, _xlfn.XLOOKUP(TRIM(D10), Settings!$F$4:$F$101, Settings!$H$4:$H$101, 0), _xlpm.life, _xlfn.XLOOKUP(TRIM(D10), Settings!$F$4:$F$101, Settings!$I$4:$I$101, 1), _xlpm.pct, _xlfn.XLOOKUP(TRIM(D10), Settings!$F$4:$F$101, Settings!$J$4:$J$101, 0), _xlpm.qty * _xlpm.hours * (_xlpm.price / _xlpm.life * _xlpm.pct) ) -> 940 | Q10: =Jobs[[#This Row],[Post Pro/h]]*Settings!$D$18 -> 0 | R10: =(Jobs[[#This Row],[power/t]]+Jobs[[#This Row],[Matrial/t]]+Jobs[[#This Row],[downturn/t]]+Jobs[[#This Row],[Maintenance/t]]+Jobs[[#This Row],[Coloring/t]]+Jobs[[#This Row],[Extras]])*Settings!$D$12 -> 22331.232 | S10: =Jobs[[#This Row],[Matrial/t]] + Jobs[[#This Row],[power/t]] + Jobs[[#This Row],[downturn/t]] + Jobs[[#This Row],[Maintenance/t]] + Jobs[[#This Row],[Coloring/t]] + Jobs[[#This Row],[overhead/t]] + Jobs[[#This Row],[Extras]] -> 96768.672 | T10: =S10*(1+Settings!$D$5) -> 290306.02 | U10: =Jobs[[#This Row],[Sugested Price/t]] - Jobs[[#This Row],[base price/t]] -> 193537.34 | V10: =IFERROR(Jobs[[#This Row],[Gross margin/t]] / Jobs[[#This Row],[base price/t]], 0) -> 2
B11: چای کابل بال | C11: 1 | D11: Anycubic Kobra S1- office | E11: PLA | F11: Black | G11: 11 | J11: 0.055555556 | M11: =_xlfn.LET( _xlpm.qty, C11, _xlpm.weight_g, G11 + H11 + Jobs[[#This Row],[Flushed/g]], _xlpm.material, TRIM(E11), _xlpm.price_per_kg, _xlfn.XLOOKUP(_xlpm.material, MaterialsTbl[Material], MaterialsTbl[Price_per_kg], 0), _xlpm.waste_pct, _xlfn.XLOOKUP(_xlpm.material, MaterialsTbl[Material], MaterialsTbl[Waste_pct], 0), _xlpm.qty * (_xlpm.weight_g / 1000) * _xlpm.price_per_kg * (1 + _xlpm.waste_pct) ) -> 30030 | N11: =_xlfn.LET( _xlpm.qty, C11, _xlpm.hours, J11*24, _xlpm.power_w, _xlfn.XLOOKUP(TRIM(D11), Settings!$F$4:$F$101, Settings!$G$4:$G$101, 120), _xlpm.rate, Settings!$D$4, _xlpm.qty * _xlpm.hours * (_xlpm.power_w / 1000) * _xlpm.rate ) -> 129.92 | O11: =_xlfn.LET( _xlpm.qty, C11, _xlpm.hours, J11*24, _xlpm.price, _xlfn.XLOOKUP(TRIM(D11), Settings!$F$4:$F$101, Settings!$H$4:$H$101, 0), _xlpm.life, _xlfn.XLOOKUP(TRIM(D11), Settings!$F$4:$F$101, Settings!$I$4:$I$101, 1), _xlpm.qty * _xlpm.hours * (_xlpm.price / _xlpm.life) ) -> 25066.667 | P11: =_xlfn.LET( _xlpm.qty, C11, _xlpm.hours, J11*24, _xlpm.price, _xlfn.XLOOKUP(TRIM(D11), Settings!$F$4:$F$101, Settings!$H$4:$H$101, 0), _xlpm.life, _xlfn.XLOOKUP(TRIM(D11), Settings!$F$4:$F$101, Settings!$I$4:$I$101, 1), _xlpm.pct, _xlfn.XLOOKUP(TRIM(D11), Settings!$F$4:$F$101, Settings!$J$4:$J$101, 0), _xlpm.qty * _xlpm.hours * (_xlpm.price / _xlpm.life * _xlpm.pct) ) -> 1253.3333 | Q11: =Jobs[[#This Row],[Post Pro/h]]*Settings!$D$18 -> 0 | R11: =(Jobs[[#This Row],[power/t]]+Jobs[[#This Row],[Matrial/t]]+Jobs[[#This Row],[downturn/t]]+Jobs[[#This Row],[Maintenance/t]]+Jobs[[#This Row],[Coloring/t]]+Jobs[[#This Row],[Extras]])*Settings!$D$12 -> 16943.976 | S11: =Jobs[[#This Row],[Matrial/t]] + Jobs[[#This Row],[power/t]] + Jobs[[#This Row],[downturn/t]] + Jobs[[#This Row],[Maintenance/t]] + Jobs[[#This Row],[Coloring/t]] + Jobs[[#This Row],[overhead/t]] + Jobs[[#This Row],[Extras]] -> 73423.896 | T11: =S11*(1+Settings!$D$5) -> 220271.69 | U11: =Jobs[[#This Row],[Sugested Price/t]] - Jobs[[#This Row],[base price/t]] -> 146847.79 | V11: =IFERROR(Jobs[[#This Row],[Gross margin/t]] / Jobs[[#This Row],[base price/t]], 0) -> 2
B12: طرح نایک | C12: 1 | D12: Anycubic Kobra S1- office | E12: PLA | F12: Black | G12: 4.5 | H12: 0 | I12: 0 | J12: 0.020833333 | M12: =_xlfn.LET( _xlpm.qty, C12, _xlpm.weight_g, G12 + H12 + Jobs[[#This Row],[Flushed/g]], _xlpm.material, TRIM(E12), _xlpm.price_per_kg, _xlfn.XLOOKUP(_xlpm.material, MaterialsTbl[Material], MaterialsTbl[Price_per_kg], 0), _xlpm.waste_pct, _xlfn.XLOOKUP(_xlpm.material, MaterialsTbl[Material], MaterialsTbl[Waste_pct], 0), _xlpm.qty * (_xlpm.weight_g / 1000) * _xlpm.price_per_kg * (1 + _xlpm.waste_pct) ) -> 12285 | N12: =_xlfn.LET( _xlpm.qty, C12, _xlpm.hours, J12*24, _xlpm.power_w, _xlfn.XLOOKUP(TRIM(D12), Settings!$F$4:$F$101, Settings!$G$4:$G$101, 120), _xlpm.rate, Settings!$D$4, _xlpm.qty * _xlpm.hours * (_xlpm.power_w / 1000) * _xlpm.rate ) -> 48.72 | O12: =_xlfn.LET( _xlpm.qty, C12, _xlpm.hours, J12*24, _xlpm.price, _xlfn.XLOOKUP(TRIM(D12), Settings!$F$4:$F$101, Settings!$H$4:$H$101, 0), _xlpm.life, _xlfn.XLOOKUP(TRIM(D12), Settings!$F$4:$F$101, Settings!$I$4:$I$101, 1), _xlpm.qty * _xlpm.hours * (_xlpm.price / _xlpm.life) ) -> 9400 | P12: =_xlfn.LET( _xlpm.qty, C12, _xlpm.hours, J12*24, _xlpm.price, _xlfn.XLOOKUP(TRIM(D12), Settings!$F$4:$F$101, Settings!$H$4:$H$101, 0), _xlpm.life, _xlfn.XLOOKUP(TRIM(D12), Settings!$F$4:$F$101, Settings!$I$4:$I$101, 1), _xlpm.pct, _xlfn.XLOOKUP(TRIM(D12), Settings!$F$4:$F$101, Settings!$J$4:$J$101, 0), _xlpm.qty * _xlpm.hours * (_xlpm.price / _xlpm.life * _xlpm.pct) ) -> 470 | Q12: =Jobs[[#This Row],[Post Pro/h]]*Settings!$D$18 -> 0 | R12: =(Jobs[[#This Row],[power/t]]+Jobs[[#This Row],[Matrial/t]]+Jobs[[#This Row],[downturn/t]]+Jobs[[#This Row],[Maintenance/t]]+Jobs[[#This Row],[Coloring/t]]+Jobs[[#This Row],[Extras]])*Settings!$D$12 -> 6661.116 | S12: =Jobs[[#This Row],[Matrial/t]] + Jobs[[#This Row],[power/t]] + Jobs[[#This Row],[downturn/t]] + Jobs[[#This Row],[Maintenance/t]] + Jobs[[#This Row],[Coloring/t]] + Jobs[[#This Row],[overhead/t]] + Jobs[[#This Row],[Extras]] -> 28864.836 | T12: =S12*(1+Settings!$D$5) -> 86594.508 | U12: =Jobs[[#This Row],[Sugested Price/t]] - Jobs[[#This Row],[base price/t]] -> 57729.672 | V12: =IFERROR(Jobs[[#This Row],[Gross margin/t]] / Jobs[[#This Row],[base price/t]], 0) -> 2
B13: گوشواره روتاری | C13: 2 | D13: Anycubic Kobra S1- office | E13: PLA | F13: Black | G13: 5 | J13: 0.03125 | M13: =_xlfn.LET( _xlpm.qty, C13, _xlpm.weight_g, G13 + H13 + Jobs[[#This Row],[Flushed/g]], _xlpm.material, TRIM(E13), _xlpm.price_per_kg, _xlfn.XLOOKUP(_xlpm.material, MaterialsTbl[Material], MaterialsTbl[Price_per_kg], 0), _xlpm.waste_pct, _xlfn.XLOOKUP(_xlpm.material, MaterialsTbl[Material], MaterialsTbl[Waste_pct], 0), _xlpm.qty * (_xlpm.weight_g / 1000) * _xlpm.price_per_kg * (1 + _xlpm.waste_pct) ) -> 27300 | N13: =_xlfn.LET( _xlpm.qty, C13, _xlpm.hours, J13*24, _xlpm.power_w, _xlfn.XLOOKUP(TRIM(D13), Settings!$F$4:$F$101, Settings!$G$4:$G$101, 120), _xlpm.rate, Settings!$D$4, _xlpm.qty * _xlpm.hours * (_xlpm.power_w / 1000) * _xlpm.rate ) -> 146.16 | O13: =_xlfn.LET( _xlpm.qty, C13, _xlpm.hours, J13*24, _xlpm.price, _xlfn.XLOOKUP(TRIM(D13), Settings!$F$4:$F$101, Settings!$H$4:$H$101, 0), _xlpm.life, _xlfn.XLOOKUP(TRIM(D13), Settings!$F$4:$F$101, Settings!$I$4:$I$101, 1), _xlpm.qty * _xlpm.hours * (_xlpm.price / _xlpm.life) ) -> 28200 | P13: =_xlfn.LET( _xlpm.qty, C13, _xlpm.hours, J13*24, _xlpm.price, _xlfn.XLOOKUP(TRIM(D13), Settings!$F$4:$F$101, Settings!$H$4:$H$101, 0), _xlpm.life, _xlfn.XLOOKUP(TRIM(D13), Settings!$F$4:$F$101, Settings!$I$4:$I$101, 1), _xlpm.pct, _xlfn.XLOOKUP(TRIM(D13), Settings!$F$4:$F$101, Settings!$J$4:$J$101, 0), _xlpm.qty * _xlpm.hours * (_xlpm.price / _xlpm.life * _xlpm.pct) ) -> 1410 | Q13: =Jobs[[#This Row],[Post Pro/h]]*Settings!$D$18 -> 0 | R13: =(Jobs[[#This Row],[power/t]]+Jobs[[#This Row],[Matrial/t]]+Jobs[[#This Row],[downturn/t]]+Jobs[[#This Row],[Maintenance/t]]+Jobs[[#This Row],[Coloring/t]]+Jobs[[#This Row],[Extras]])*Settings!$D$12 -> 17116.848 | S13: =Jobs[[#This Row],[Matrial/t]] + Jobs[[#This Row],[power/t]] + Jobs[[#This Row],[downturn/t]] + Jobs[[#This Row],[Maintenance/t]] + Jobs[[#This Row],[Coloring/t]] + Jobs[[#This Row],[overhead/t]] + Jobs[[#This Row],[Extras]] -> 74173.008 | T13: =S13*(1+Settings!$D$5) -> 222519.02 | U13: =Jobs[[#This Row],[Sugested Price/t]] - Jobs[[#This Row],[base price/t]] -> 148346.02 | V13: =IFERROR(Jobs[[#This Row],[Gross margin/t]] / Jobs[[#This Row],[base price/t]], 0) -> 2
B14: کلاه کابویی | C14: 1 | D14: Anycubic Kobra S1- office | E14: PLA | F14: Black | G14: 6 | J14: 0.03125 | M14: =_xlfn.LET( _xlpm.qty, C14, _xlpm.weight_g, G14 + H14 + Jobs[[#This Row],[Flushed/g]], _xlpm.material, TRIM(E14), _xlpm.price_per_kg, _xlfn.XLOOKUP(_xlpm.material, MaterialsTbl[Material], MaterialsTbl[Price_per_kg], 0), _xlpm.waste_pct, _xlfn.XLOOKUP(_xlpm.material, MaterialsTbl[Material], MaterialsTbl[Waste_pct], 0), _xlpm.qty * (_xlpm.weight_g / 1000) * _xlpm.price_per_kg * (1 + _xlpm.waste_pct) ) -> 16380 | N14: =_xlfn.LET( _xlpm.qty, C14, _xlpm.hours, J14*24, _xlpm.power_w, _xlfn.XLOOKUP(TRIM(D14), Settings!$F$4:$F$101, Settings!$G$4:$G$101, 120), _xlpm.rate, Settings!$D$4, _xlpm.qty * _xlpm.hours * (_xlpm.power_w / 1000) * _xlpm.rate ) -> 73.08 | O14: =_xlfn.LET( _xlpm.qty, C14, _xlpm.hours, J14*24, _xlpm.price, _xlfn.XLOOKUP(TRIM(D14), Settings!$F$4:$F$101, Settings!$H$4:$H$101, 0), _xlpm.life, _xlfn.XLOOKUP(TRIM(D14), Settings!$F$4:$F$101, Settings!$I$4:$I$101, 1), _xlpm.qty * _xlpm.hours * (_xlpm.price / _xlpm.life) ) -> 14100 | P14: =_xlfn.LET( _xlpm.qty, C14, _xlpm.hours, J14*24, _xlpm.price, _xlfn.XLOOKUP(TRIM(D14), Settings!$F$4:$F$101, Settings!$H$4:$H$101, 0), _xlpm.life, _xlfn.XLOOKUP(TRIM(D14), Settings!$F$4:$F$101, Settings!$I$4:$I$101, 1), _xlpm.pct, _xlfn.XLOOKUP(TRIM(D14), Settings!$F$4:$F$101, Settings!$J$4:$J$101, 0), _xlpm.qty * _xlpm.hours * (_xlpm.price / _xlpm.life * _xlpm.pct) ) -> 705 | Q14: =Jobs[[#This Row],[Post Pro/h]]*Settings!$D$18 -> 0 | R14: =(Jobs[[#This Row],[power/t]]+Jobs[[#This Row],[Matrial/t]]+Jobs[[#This Row],[downturn/t]]+Jobs[[#This Row],[Maintenance/t]]+Jobs[[#This Row],[Coloring/t]]+Jobs[[#This Row],[Extras]])*Settings!$D$12 -> 9377.424 | S14: =Jobs[[#This Row],[Matrial/t]] + Jobs[[#This Row],[power/t]] + Jobs[[#This Row],[downturn/t]] + Jobs[[#This Row],[Maintenance/t]] + Jobs[[#This Row],[Coloring/t]] + Jobs[[#This Row],[overhead/t]] + Jobs[[#This Row],[Extras]] -> 40635.504 | T14: =S14*(1+Settings!$D$5) -> 121906.51 | U14: =Jobs[[#This Row],[Sugested Price/t]] - Jobs[[#This Row],[base price/t]] -> 81271.008 | V14: =IFERROR(Jobs[[#This Row],[Gross margin/t]] / Jobs[[#This Row],[base price/t]], 0) -> 2
B15: شیپ طوری | C15: 1 | D15: Anycubic Kobra S1- office | E15: PLA | F15: Black | G15: 7 | J15: 0.024305556 | M15: =_xlfn.LET( _xlpm.qty, C15, _xlpm.weight_g, G15 + H15 + Jobs[[#This Row],[Flushed/g]], _xlpm.material, TRIM(E15), _xlpm.price_per_kg, _xlfn.XLOOKUP(_xlpm.material, MaterialsTbl[Material], MaterialsTbl[Price_per_kg], 0), _xlpm.waste_pct, _xlfn.XLOOKUP(_xlpm.material, MaterialsTbl[Material], MaterialsTbl[Waste_pct], 0), _xlpm.qty * (_xlpm.weight_g / 1000) * _xlpm.price_per_kg * (1 + _xlpm.waste_pct) ) -> 19110 | N15: =_xlfn.LET( _xlpm.qty, C15, _xlpm.hours, J15*24, _xlpm.power_w, _xlfn.XLOOKUP(TRIM(D15), Settings!$F$4:$F$101, Settings!$G$4:$G$101, 120), _xlpm.rate, Settings!$D$4, _xlpm.qty * _xlpm.hours * (_xlpm.power_w / 1000) * _xlpm.rate ) -> 56.84 | O15: =_xlfn.LET( _xlpm.qty, C15, _xlpm.hours, J15*24, _xlpm.price, _xlfn.XLOOKUP(TRIM(D15), Settings!$F$4:$F$101, Settings!$H$4:$H$101, 0), _xlpm.life, _xlfn.XLOOKUP(TRIM(D15), Settings!$F$4:$F$101, Settings!$I$4:$I$101, 1), _xlpm.qty * _xlpm.hours * (_xlpm.price / _xlpm.life) ) -> 10966.667 | P15: =_xlfn.LET( _xlpm.qty, C15, _xlpm.hours, J15*24, _xlpm.price, _xlfn.XLOOKUP(TRIM(D15), Settings!$F$4:$F$101, Settings!$H$4:$H$101, 0), _xlpm.life, _xlfn.XLOOKUP(TRIM(D15), Settings!$F$4:$F$101, Settings!$I$4:$I$101, 1), _xlpm.pct, _xlfn.XLOOKUP(TRIM(D15), Settings!$F$4:$F$101, Settings!$J$4:$J$101, 0), _xlpm.qty * _xlpm.hours * (_xlpm.price / _xlpm.life * _xlpm.pct) ) -> 548.33333 | Q15: =Jobs[[#This Row],[Post Pro/h]]*Settings!$D$18 -> 0 | R15: =(Jobs[[#This Row],[power/t]]+Jobs[[#This Row],[Matrial/t]]+Jobs[[#This Row],[downturn/t]]+Jobs[[#This Row],[Maintenance/t]]+Jobs[[#This Row],[Coloring/t]]+Jobs[[#This Row],[Extras]])*Settings!$D$12 -> 9204.552 | S15: =Jobs[[#This Row],[Matrial/t]] + Jobs[[#This Row],[power/t]] + Jobs[[#This Row],[downturn/t]] + Jobs[[#This Row],[Maintenance/t]] + Jobs[[#This Row],[Coloring/t]] + Jobs[[#This Row],[overhead/t]] + Jobs[[#This Row],[Extras]] -> 39886.392 | T15: =S15*(1+Settings!$D$5) -> 119659.18 | U15: =Jobs[[#This Row],[Sugested Price/t]] - Jobs[[#This Row],[base price/t]] -> 79772.784 | V15: =IFERROR(Jobs[[#This Row],[Gross margin/t]] / Jobs[[#This Row],[base price/t]], 0) -> 2
B16: کلیپس پروانه | C16: 1 | D16: Anycubic Kobra S1- office | E16: PLA | F16: Black | G16: 16 | H16: 8 | J16: 0.09375 | M16: =_xlfn.LET( _xlpm.qty, C16, _xlpm.weight_g, G16 + H16 + Jobs[[#This Row],[Flushed/g]], _xlpm.material, TRIM(E16), _xlpm.price_per_kg, _xlfn.XLOOKUP(_xlpm.material, MaterialsTbl[Material], MaterialsTbl[Price_per_kg], 0), _xlpm.waste_pct, _xlfn.XLOOKUP(_xlpm.material, MaterialsTbl[Material], MaterialsTbl[Waste_pct], 0), _xlpm.qty * (_xlpm.weight_g / 1000) * _xlpm.price_per_kg * (1 + _xlpm.waste_pct) ) -> 65520 | N16: =_xlfn.LET( _xlpm.qty, C16, _xlpm.hours, J16*24, _xlpm.power_w, _xlfn.XLOOKUP(TRIM(D16), Settings!$F$4:$F$101, Settings!$G$4:$G$101, 120), _xlpm.rate, Settings!$D$4, _xlpm.qty * _xlpm.hours * (_xlpm.power_w / 1000) * _xlpm.rate ) -> 219.24 | O16: =_xlfn.LET( _xlpm.qty, C16, _xlpm.hours, J16*24, _xlpm.price, _xlfn.XLOOKUP(TRIM(D16), Settings!$F$4:$F$101, Settings!$H$4:$H$101, 0), _xlpm.life, _xlfn.XLOOKUP(TRIM(D16), Settings!$F$4:$F$101, Settings!$I$4:$I$101, 1), _xlpm.qty * _xlpm.hours * (_xlpm.price / _xlpm.life) ) -> 42300 | P16: =_xlfn.LET( _xlpm.qty, C16, _xlpm.hours, J16*24, _xlpm.price, _xlfn.XLOOKUP(TRIM(D16), Settings!$F$4:$F$101, Settings!$H$4:$H$101, 0), _xlpm.life, _xlfn.XLOOKUP(TRIM(D16), Settings!$F$4:$F$101, Settings!$I$4:$I$101, 1), _xlpm.pct, _xlfn.XLOOKUP(TRIM(D16), Settings!$F$4:$F$101, Settings!$J$4:$J$101, 0), _xlpm.qty * _xlpm.hours * (_xlpm.price / _xlpm.life * _xlpm.pct) ) -> 2115 | Q16: =Jobs[[#This Row],[Post Pro/h]]*Settings!$D$18 -> 0 | R16: =(Jobs[[#This Row],[power/t]]+Jobs[[#This Row],[Matrial/t]]+Jobs[[#This Row],[downturn/t]]+Jobs[[#This Row],[Maintenance/t]]+Jobs[[#This Row],[Coloring/t]]+Jobs[[#This Row],[Extras]])*Settings!$D$12 -> 33046.272 | S16: =Jobs[[#This Row],[Matrial/t]] + Jobs[[#This Row],[power/t]] + Jobs[[#This Row],[downturn/t]] + Jobs[[#This Row],[Maintenance/t]] + Jobs[[#This Row],[Coloring/t]] + Jobs[[#This Row],[overhead/t]] + Jobs[[#This Row],[Extras]] -> 143200.51 | T16: =S16*(1+Settings!$D$5) -> 429601.54 | U16: =Jobs[[#This Row],[Sugested Price/t]] - Jobs[[#This Row],[base price/t]] -> 286401.02 | V16: =IFERROR(Jobs[[#This Row],[Gross margin/t]] / Jobs[[#This Row],[base price/t]], 0) -> 2
B17: گوشواره دیویل ور پرادا | C17: 1 | D17: Anycubic Kobra S1- office | E17: PLA | F17: Black | G17: 151 | J17: 0.30208333 | M17: =_xlfn.LET( _xlpm.qty, C17, _xlpm.weight_g, G17 + H17 + Jobs[[#This Row],[Flushed/g]], _xlpm.material, TRIM(E17), _xlpm.price_per_kg, _xlfn.XLOOKUP(_xlpm.material, MaterialsTbl[Material], MaterialsTbl[Price_per_kg], 0), _xlpm.waste_pct, _xlfn.XLOOKUP(_xlpm.material, MaterialsTbl[Material], MaterialsTbl[Waste_pct], 0), _xlpm.qty * (_xlpm.weight_g / 1000) * _xlpm.price_per_kg * (1 + _xlpm.waste_pct) ) -> 412230 | N17: =_xlfn.LET( _xlpm.qty, C17, _xlpm.hours, J17*24, _xlpm.power_w, _xlfn.XLOOKUP(TRIM(D17), Settings!$F$4:$F$101, Settings!$G$4:$G$101, 120), _xlpm.rate, Settings!$D$4, _xlpm.qty * _xlpm.hours * (_xlpm.power_w / 1000) * _xlpm.rate ) -> 706.44 | O17: =_xlfn.LET( _xlpm.qty, C17, _xlpm.hours, J17*24, _xlpm.price, _xlfn.XLOOKUP(TRIM(D17), Settings!$F$4:$F$101, Settings!$H$4:$H$101, 0), _xlpm.life, _xlfn.XLOOKUP(TRIM(D17), Settings!$F$4:$F$101, Settings!$I$4:$I$101, 1), _xlpm.qty * _xlpm.hours * (_xlpm.price / _xlpm.life) ) -> 136300 | P17: =_xlfn.LET( _xlpm.qty, C17, _xlpm.hours, J17*24, _xlpm.price, _xlfn.XLOOKUP(TRIM(D17), Settings!$F$4:$F$101, Settings!$H$4:$H$101, 0), _xlpm.life, _xlfn.XLOOKUP(TRIM(D17), Settings!$F$4:$F$101, Settings!$I$4:$I$101, 1), _xlpm.pct, _xlfn.XLOOKUP(TRIM(D17), Settings!$F$4:$F$101, Settings!$J$4:$J$101, 0), _xlpm.qty * _xlpm.hours * (_xlpm.price / _xlpm.life * _xlpm.pct) ) -> 6815 | Q17: =Jobs[[#This Row],[Post Pro/h]]*Settings!$D$18 -> 0 | R17: =(Jobs[[#This Row],[power/t]]+Jobs[[#This Row],[Matrial/t]]+Jobs[[#This Row],[downturn/t]]+Jobs[[#This Row],[Maintenance/t]]+Jobs[[#This Row],[Coloring/t]]+Jobs[[#This Row],[Extras]])*Settings!$D$12 -> 166815.43 | S17: =Jobs[[#This Row],[Matrial/t]] + Jobs[[#This Row],[power/t]] + Jobs[[#This Row],[downturn/t]] + Jobs[[#This Row],[Maintenance/t]] + Jobs[[#This Row],[Coloring/t]] + Jobs[[#This Row],[overhead/t]] + Jobs[[#This Row],[Extras]] -> 722866.87 | T17: =S17*(1+Settings!$D$5) -> 2168600.6 | U17: =Jobs[[#This Row],[Sugested Price/t]] - Jobs[[#This Row],[base price/t]] -> 1445733.7 | V17: =IFERROR(Jobs[[#This Row],[Gross margin/t]] / Jobs[[#This Row],[base price/t]], 0) -> 2
B18: انگشتر ژرمن شپرد | C18: 1 | D18: Anycubic Kobra S1- office | E18: PLA | F18: white | G18: 2 | J18: 0.020833333 | K18: 0 | L18: 150000 | M18: =_xlfn.LET( _xlpm.qty, C18, _xlpm.weight_g, G18 + H18 + Jobs[[#This Row],[Flushed/g]], _xlpm.material, TRIM(E18), _xlpm.price_per_kg, _xlfn.XLOOKUP(_xlpm.material, MaterialsTbl[Material], MaterialsTbl[Price_per_kg], 0), _xlpm.waste_pct, _xlfn.XLOOKUP(_xlpm.material, MaterialsTbl[Material], MaterialsTbl[Waste_pct], 0), _xlpm.qty * (_xlpm.weight_g / 1000) * _xlpm.price_per_kg * (1 + _xlpm.waste_pct) ) -> 5460 | N18: =_xlfn.LET( _xlpm.qty, C18, _xlpm.hours, J18*24, _xlpm.power_w, _xlfn.XLOOKUP(TRIM(D18), Settings!$F$4:$F$101, Settings!$G$4:$G$101, 120), _xlpm.rate, Settings!$D$4, _xlpm.qty * _xlpm.hours * (_xlpm.power_w / 1000) * _xlpm.rate ) -> 48.72 | O18: =_xlfn.LET( _xlpm.qty, C18, _xlpm.hours, J18*24, _xlpm.price, _xlfn.XLOOKUP(TRIM(D18), Settings!$F$4:$F$101, Settings!$H$4:$H$101, 0), _xlpm.life, _xlfn.XLOOKUP(TRIM(D18), Settings!$F$4:$F$101, Settings!$I$4:$I$101, 1), _xlpm.qty * _xlpm.hours * (_xlpm.price / _xlpm.life) ) -> 9400 | P18: =_xlfn.LET( _xlpm.qty, C18, _xlpm.hours, J18*24, _xlpm.price, _xlfn.XLOOKUP(TRIM(D18), Settings!$F$4:$F$101, Settings!$H$4:$H$101, 0), _xlpm.life, _xlfn.XLOOKUP(TRIM(D18), Settings!$F$4:$F$101, Settings!$I$4:$I$101, 1), _xlpm.pct, _xlfn.XLOOKUP(TRIM(D18), Settings!$F$4:$F$101, Settings!$J$4:$J$101, 0), _xlpm.qty * _xlpm.hours * (_xlpm.price / _xlpm.life * _xlpm.pct) ) -> 470 | Q18: =Jobs[[#This Row],[Post Pro/h]]*Settings!$D$18 -> 0 | R18: =(Jobs[[#This Row],[power/t]]+Jobs[[#This Row],[Matrial/t]]+Jobs[[#This Row],[downturn/t]]+Jobs[[#This Row],[Maintenance/t]]+Jobs[[#This Row],[Coloring/t]]+Jobs[[#This Row],[Extras]])*Settings!$D$12 -> 49613.616 | S18: =Jobs[[#This Row],[Matrial/t]] + Jobs[[#This Row],[power/t]] + Jobs[[#This Row],[downturn/t]] + Jobs[[#This Row],[Maintenance/t]] + Jobs[[#This Row],[Coloring/t]] + Jobs[[#This Row],[overhead/t]] + Jobs[[#This Row],[Extras]] -> 214992.34 | T18: =S18*(1+Settings!$D$5) -> 644977.01 | U18: =Jobs[[#This Row],[Sugested Price/t]] - Jobs[[#This Row],[base price/t]] -> 429984.67 | V18: =IFERROR(Jobs[[#This Row],[Gross margin/t]] / Jobs[[#This Row],[base price/t]], 0) -> 2
B19: گوشواره دلفین | C19: 1 | D19: Anycubic Kobra S1- office | E19: PLA | F19: Black | M19: =_xlfn.LET( _xlpm.qty, C19, _xlpm.weight_g, G19 + H19 + Jobs[[#This Row],[Flushed/g]], _xlpm.material, TRIM(E19), _xlpm.price_per_kg, _xlfn.XLOOKUP(_xlpm.material, MaterialsTbl[Material], MaterialsTbl[Price_per_kg], 0), _xlpm.waste_pct, _xlfn.XLOOKUP(_xlpm.material, MaterialsTbl[Material], MaterialsTbl[Waste_pct], 0), _xlpm.qty * (_xlpm.weight_g / 1000) * _xlpm.price_per_kg * (1 + _xlpm.waste_pct) ) -> 0 | N19: =_xlfn.LET( _xlpm.qty, C19, _xlpm.hours, J19*24, _xlpm.power_w, _xlfn.XLOOKUP(TRIM(D19), Settings!$F$4:$F$101, Settings!$G$4:$G$101, 120), _xlpm.rate, Settings!$D$4, _xlpm.qty * _xlpm.hours * (_xlpm.power_w / 1000) * _xlpm.rate ) -> 0 | O19: =_xlfn.LET( _xlpm.qty, C19, _xlpm.hours, J19*24, _xlpm.price, _xlfn.XLOOKUP(TRIM(D19), Settings!$F$4:$F$101, Settings!$H$4:$H$101, 0), _xlpm.life, _xlfn.XLOOKUP(TRIM(D19), Settings!$F$4:$F$101, Settings!$I$4:$I$101, 1), _xlpm.qty * _xlpm.hours * (_xlpm.price / _xlpm.life) ) -> 0 | P19: =_xlfn.LET( _xlpm.qty, C19, _xlpm.hours, J19*24, _xlpm.price, _xlfn.XLOOKUP(TRIM(D19), Settings!$F$4:$F$101, Settings!$H$4:$H$101, 0), _xlpm.life, _xlfn.XLOOKUP(TRIM(D19), Settings!$F$4:$F$101, Settings!$I$4:$I$101, 1), _xlpm.pct, _xlfn.XLOOKUP(TRIM(D19), Settings!$F$4:$F$101, Settings!$J$4:$J$101, 0), _xlpm.qty * _xlpm.hours * (_xlpm.price / _xlpm.life * _xlpm.pct) ) -> 0 | Q19: =Jobs[[#This Row],[Post Pro/h]]*Settings!$D$18 -> 0 | R19: =(Jobs[[#This Row],[power/t]]+Jobs[[#This Row],[Matrial/t]]+Jobs[[#This Row],[downturn/t]]+Jobs[[#This Row],[Maintenance/t]]+Jobs[[#This Row],[Coloring/t]]+Jobs[[#This Row],[Extras]])*Settings!$D$12 -> 0 | S19: =Jobs[[#This Row],[Matrial/t]] + Jobs[[#This Row],[power/t]] + Jobs[[#This Row],[downturn/t]] + Jobs[[#This Row],[Maintenance/t]] + Jobs[[#This Row],[Coloring/t]] + Jobs[[#This Row],[overhead/t]] + Jobs[[#This Row],[Extras]] -> 0 | T19: =S19*(1+Settings!$D$5) -> 0 | U19: =Jobs[[#This Row],[Sugested Price/t]] - Jobs[[#This Row],[base price/t]] -> 0 | V19: =IFERROR(Jobs[[#This Row],[Gross margin/t]] / Jobs[[#This Row],[base price/t]], 0) -> 0
B20: گوشواره ببر | C20: 1 | D20: Anycubic Kobra S1- office | E20: PLA | F20: orange | G20: 5.12 | J20: 0.03125 | M20: =_xlfn.LET( _xlpm.qty, C20, _xlpm.weight_g, G20 + H20 + Jobs[[#This Row],[Flushed/g]], _xlpm.material, TRIM(E20), _xlpm.price_per_kg, _xlfn.XLOOKUP(_xlpm.material, MaterialsTbl[Material], MaterialsTbl[Price_per_kg], 0), _xlpm.waste_pct, _xlfn.XLOOKUP(_xlpm.material, MaterialsTbl[Material], MaterialsTbl[Waste_pct], 0), _xlpm.qty * (_xlpm.weight_g / 1000) * _xlpm.price_per_kg * (1 + _xlpm.waste_pct) ) -> 13977.6 | N20: =_xlfn.LET( _xlpm.qty, C20, _xlpm.hours, J20*24, _xlpm.power_w, _xlfn.XLOOKUP(TRIM(D20), Settings!$F$4:$F$101, Settings!$G$4:$G$101, 120), _xlpm.rate, Settings!$D$4, _xlpm.qty * _xlpm.hours * (_xlpm.power_w / 1000) * _xlpm.rate ) -> 73.08 | O20: =_xlfn.LET( _xlpm.qty, C20, _xlpm.hours, J20*24, _xlpm.price, _xlfn.XLOOKUP(TRIM(D20), Settings!$F$4:$F$101, Settings!$H$4:$H$101, 0), _xlpm.life, _xlfn.XLOOKUP(TRIM(D20), Settings!$F$4:$F$101, Settings!$I$4:$I$101, 1), _xlpm.qty * _xlpm.hours * (_xlpm.price / _xlpm.life) ) -> 14100 | P20: =_xlfn.LET( _xlpm.qty, C20, _xlpm.hours, J20*24, _xlpm.price, _xlfn.XLOOKUP(TRIM(D20), Settings!$F$4:$F$101, Settings!$H$4:$H$101, 0), _xlpm.life, _xlfn.XLOOKUP(TRIM(D20), Settings!$F$4:$F$101, Settings!$I$4:$I$101, 1), _xlpm.pct, _xlfn.XLOOKUP(TRIM(D20), Settings!$F$4:$F$101, Settings!$J$4:$J$101, 0), _xlpm.qty * _xlpm.hours * (_xlpm.price / _xlpm.life * _xlpm.pct) ) -> 705 | Q20: =Jobs[[#This Row],[Post Pro/h]]*Settings!$D$18 -> 0 | R20: =(Jobs[[#This Row],[power/t]]+Jobs[[#This Row],[Matrial/t]]+Jobs[[#This Row],[downturn/t]]+Jobs[[#This Row],[Maintenance/t]]+Jobs[[#This Row],[Coloring/t]]+Jobs[[#This Row],[Extras]])*Settings!$D$12 -> 8656.704 | S20: =Jobs[[#This Row],[Matrial/t]] + Jobs[[#This Row],[power/t]] + Jobs[[#This Row],[downturn/t]] + Jobs[[#This Row],[Maintenance/t]] + Jobs[[#This Row],[Coloring/t]] + Jobs[[#This Row],[overhead/t]] + Jobs[[#This Row],[Extras]] -> 37512.384 | T20: =S20*(1+Settings!$D$5) -> 112537.15 | U20: =Jobs[[#This Row],[Sugested Price/t]] - Jobs[[#This Row],[base price/t]] -> 75024.768 | V20: =IFERROR(Jobs[[#This Row],[Gross margin/t]] / Jobs[[#This Row],[base price/t]], 0) -> 2
B21: جاسویچی آیفون | C21: 1 | D21: Anycubic Kobra S1- office | E21: PLA | F21: Black | G21: 3 | J21: 0.013888889 | M21: =_xlfn.LET( _xlpm.qty, C21, _xlpm.weight_g, G21 + H21 + Jobs[[#This Row],[Flushed/g]], _xlpm.material, TRIM(E21), _xlpm.price_per_kg, _xlfn.XLOOKUP(_xlpm.material, MaterialsTbl[Material], MaterialsTbl[Price_per_kg], 0), _xlpm.waste_pct, _xlfn.XLOOKUP(_xlpm.material, MaterialsTbl[Material], MaterialsTbl[Waste_pct], 0), _xlpm.qty * (_xlpm.weight_g / 1000) * _xlpm.price_per_kg * (1 + _xlpm.waste_pct) ) -> 8190 | N21: =_xlfn.LET( _xlpm.qty, C21, _xlpm.hours, J21*24, _xlpm.power_w, _xlfn.XLOOKUP(TRIM(D21), Settings!$F$4:$F$101, Settings!$G$4:$G$101, 120), _xlpm.rate, Settings!$D$4, _xlpm.qty * _xlpm.hours * (_xlpm.power_w / 1000) * _xlpm.rate ) -> 32.48 | O21: =_xlfn.LET( _xlpm.qty, C21, _xlpm.hours, J21*24, _xlpm.price, _xlfn.XLOOKUP(TRIM(D21), Settings!$F$4:$F$101, Settings!$H$4:$H$101, 0), _xlpm.life, _xlfn.XLOOKUP(TRIM(D21), Settings!$F$4:$F$101, Settings!$I$4:$I$101, 1), _xlpm.qty * _xlpm.hours * (_xlpm.price / _xlpm.life) ) -> 6266.6667 | P21: =_xlfn.LET( _xlpm.qty, C21, _xlpm.hours, J21*24, _xlpm.price, _xlfn.XLOOKUP(TRIM(D21), Settings!$F$4:$F$101, Settings!$H$4:$H$101, 0), _xlpm.life, _xlfn.XLOOKUP(TRIM(D21), Settings!$F$4:$F$101, Settings!$I$4:$I$101, 1), _xlpm.pct, _xlfn.XLOOKUP(TRIM(D21), Settings!$F$4:$F$101, Settings!$J$4:$J$101, 0), _xlpm.qty * _xlpm.hours * (_xlpm.price / _xlpm.life * _xlpm.pct) ) -> 313.33333 | Q21: =Jobs[[#This Row],[Post Pro/h]]*Settings!$D$18 -> 0 | R21: =(Jobs[[#This Row],[power/t]]+Jobs[[#This Row],[Matrial/t]]+Jobs[[#This Row],[downturn/t]]+Jobs[[#This Row],[Maintenance/t]]+Jobs[[#This Row],[Coloring/t]]+Jobs[[#This Row],[Extras]])*Settings!$D$12 -> 4440.744 | S21: =Jobs[[#This Row],[Matrial/t]] + Jobs[[#This Row],[power/t]] + Jobs[[#This Row],[downturn/t]] + Jobs[[#This Row],[Maintenance/t]] + Jobs[[#This Row],[Coloring/t]] + Jobs[[#This Row],[overhead/t]] + Jobs[[#This Row],[Extras]] -> 19243.224 | T21: =S21*(1+Settings!$D$5) -> 57729.672 | U21: =Jobs[[#This Row],[Sugested Price/t]] - Jobs[[#This Row],[base price/t]] -> 38486.448 | V21: =IFERROR(Jobs[[#This Row],[Gross margin/t]] / Jobs[[#This Row],[base price/t]], 0) -> 2
B22: اکسسوری دریا | C22: 1 | D22: Anycubic Kobra S1- office | E22: PLA | F22: Black | G22: 8 | J22: 0.024305556 | M22: =_xlfn.LET( _xlpm.qty, C22, _xlpm.weight_g, G22 + H22 + Jobs[[#This Row],[Flushed/g]], _xlpm.material, TRIM(E22), _xlpm.price_per_kg, _xlfn.XLOOKUP(_xlpm.material, MaterialsTbl[Material], MaterialsTbl[Price_per_kg], 0), _xlpm.waste_pct, _xlfn.XLOOKUP(_xlpm.material, MaterialsTbl[Material], MaterialsTbl[Waste_pct], 0), _xlpm.qty * (_xlpm.weight_g / 1000) * _xlpm.price_per_kg * (1 + _xlpm.waste_pct) ) -> 21840 | N22: =_xlfn.LET( _xlpm.qty, C22, _xlpm.hours, J22*24, _xlpm.power_w, _xlfn.XLOOKUP(TRIM(D22), Settings!$F$4:$F$101, Settings!$G$4:$G$101, 120), _xlpm.rate, Settings!$D$4, _xlpm.qty * _xlpm.hours * (_xlpm.power_w / 1000) * _xlpm.rate ) -> 56.84 | O22: =_xlfn.LET( _xlpm.qty, C22, _xlpm.hours, J22*24, _xlpm.price, _xlfn.XLOOKUP(TRIM(D22), Settings!$F$4:$F$101, Settings!$H$4:$H$101, 0), _xlpm.life, _xlfn.XLOOKUP(TRIM(D22), Settings!$F$4:$F$101, Settings!$I$4:$I$101, 1), _xlpm.qty * _xlpm.hours * (_xlpm.price / _xlpm.life) ) -> 10966.667 | P22: =_xlfn.LET( _xlpm.qty, C22, _xlpm.hours, J22*24, _xlpm.price, _xlfn.XLOOKUP(TRIM(D22), Settings!$F$4:$F$101, Settings!$H$4:$H$101, 0), _xlpm.life, _xlfn.XLOOKUP(TRIM(D22), Settings!$F$4:$F$101, Settings!$I$4:$I$101, 1), _xlpm.pct, _xlfn.XLOOKUP(TRIM(D22), Settings!$F$4:$F$101, Settings!$J$4:$J$101, 0), _xlpm.qty * _xlpm.hours * (_xlpm.price / _xlpm.life * _xlpm.pct) ) -> 548.33333 | Q22: =Jobs[[#This Row],[Post Pro/h]]*Settings!$D$18 -> 0 | R22: =(Jobs[[#This Row],[power/t]]+Jobs[[#This Row],[Matrial/t]]+Jobs[[#This Row],[downturn/t]]+Jobs[[#This Row],[Maintenance/t]]+Jobs[[#This Row],[Coloring/t]]+Jobs[[#This Row],[Extras]])*Settings!$D$12 -> 10023.552 | S22: =Jobs[[#This Row],[Matrial/t]] + Jobs[[#This Row],[power/t]] + Jobs[[#This Row],[downturn/t]] + Jobs[[#This Row],[Maintenance/t]] + Jobs[[#This Row],[Coloring/t]] + Jobs[[#This Row],[overhead/t]] + Jobs[[#This Row],[Extras]] -> 43435.392 | T22: =S22*(1+Settings!$D$5) -> 130306.18 | U22: =Jobs[[#This Row],[Sugested Price/t]] - Jobs[[#This Row],[base price/t]] -> 86870.784 | V22: =IFERROR(Jobs[[#This Row],[Gross margin/t]] / Jobs[[#This Row],[base price/t]], 0) -> 2
B23: گوشواره اژدها | C23: 1 | D23: Anycubic Kobra S1- office | E23: PLA | F23: Black | G23: 6 | J23: 0.041666667 | M23: =_xlfn.LET( _xlpm.qty, C23, _xlpm.weight_g, G23 + H23 + Jobs[[#This Row],[Flushed/g]], _xlpm.material, TRIM(E23), _xlpm.price_per_kg, _xlfn.XLOOKUP(_xlpm.material, MaterialsTbl[Material], MaterialsTbl[Price_per_kg], 0), _xlpm.waste_pct, _xlfn.XLOOKUP(_xlpm.material, MaterialsTbl[Material], MaterialsTbl[Waste_pct], 0), _xlpm.qty * (_xlpm.weight_g / 1000) * _xlpm.price_per_kg * (1 + _xlpm.waste_pct) ) -> 16380 | N23: =_xlfn.LET( _xlpm.qty, C23, _xlpm.hours, J23*24, _xlpm.power_w, _xlfn.XLOOKUP(TRIM(D23), Settings!$F$4:$F$101, Settings!$G$4:$G$101, 120), _xlpm.rate, Settings!$D$4, _xlpm.qty * _xlpm.hours * (_xlpm.power_w / 1000) * _xlpm.rate ) -> 97.44 | O23: =_xlfn.LET( _xlpm.qty, C23, _xlpm.hours, J23*24, _xlpm.price, _xlfn.XLOOKUP(TRIM(D23), Settings!$F$4:$F$101, Settings!$H$4:$H$101, 0), _xlpm.life, _xlfn.XLOOKUP(TRIM(D23), Settings!$F$4:$F$101, Settings!$I$4:$I$101, 1), _xlpm.qty * _xlpm.hours * (_xlpm.price / _xlpm.life) ) -> 18800 | P23: =_xlfn.LET( _xlpm.qty, C23, _xlpm.hours, J23*24, _xlpm.price, _xlfn.XLOOKUP(TRIM(D23), Settings!$F$4:$F$101, Settings!$H$4:$H$101, 0), _xlpm.life, _xlfn.XLOOKUP(TRIM(D23), Settings!$F$4:$F$101, Settings!$I$4:$I$101, 1), _xlpm.pct, _xlfn.XLOOKUP(TRIM(D23), Settings!$F$4:$F$101, Settings!$J$4:$J$101, 0), _xlpm.qty * _xlpm.hours * (_xlpm.price / _xlpm.life * _xlpm.pct) ) -> 940 | Q23: =Jobs[[#This Row],[Post Pro/h]]*Settings!$D$18 -> 0 | R23: =(Jobs[[#This Row],[power/t]]+Jobs[[#This Row],[Matrial/t]]+Jobs[[#This Row],[downturn/t]]+Jobs[[#This Row],[Maintenance/t]]+Jobs[[#This Row],[Coloring/t]]+Jobs[[#This Row],[Extras]])*Settings!$D$12 -> 10865.232 | S23: =Jobs[[#This Row],[Matrial/t]] + Jobs[[#This Row],[power/t]] + Jobs[[#This Row],[downturn/t]] + Jobs[[#This Row],[Maintenance/t]] + Jobs[[#This Row],[Coloring/t]] + Jobs[[#This Row],[overhead/t]] + Jobs[[#This Row],[Extras]] -> 47082.672 | T23: =S23*(1+Settings!$D$5) -> 141248.02 | U23: =Jobs[[#This Row],[Sugested Price/t]] - Jobs[[#This Row],[base price/t]] -> 94165.344 | V23: =IFERROR(Jobs[[#This Row],[Gross margin/t]] / Jobs[[#This Row],[base price/t]], 0) -> 2
B24: گوشواره گل | C24: 1 | D24: Anycubic Kobra S1- office | E24: PLA | F24: Black | G24: 2 | J24: 0.013888889 | M24: =_xlfn.LET( _xlpm.qty, C24, _xlpm.weight_g, G24 + H24 + Jobs[[#This Row],[Flushed/g]], _xlpm.material, TRIM(E24), _xlpm.price_per_kg, _xlfn.XLOOKUP(_xlpm.material, MaterialsTbl[Material], MaterialsTbl[Price_per_kg], 0), _xlpm.waste_pct, _xlfn.XLOOKUP(_xlpm.material, MaterialsTbl[Material], MaterialsTbl[Waste_pct], 0), _xlpm.qty * (_xlpm.weight_g / 1000) * _xlpm.price_per_kg * (1 + _xlpm.waste_pct) ) -> 5460 | N24: =_xlfn.LET( _xlpm.qty, C24, _xlpm.hours, J24*24, _xlpm.power_w, _xlfn.XLOOKUP(TRIM(D24), Settings!$F$4:$F$101, Settings!$G$4:$G$101, 120), _xlpm.rate, Settings!$D$4, _xlpm.qty * _xlpm.hours * (_xlpm.power_w / 1000) * _xlpm.rate ) -> 32.48 | O24: =_xlfn.LET( _xlpm.qty, C24, _xlpm.hours, J24*24, _xlpm.price, _xlfn.XLOOKUP(TRIM(D24), Settings!$F$4:$F$101, Settings!$H$4:$H$101, 0), _xlpm.life, _xlfn.XLOOKUP(TRIM(D24), Settings!$F$4:$F$101, Settings!$I$4:$I$101, 1), _xlpm.qty * _xlpm.hours * (_xlpm.price / _xlpm.life) ) -> 6266.6667 | P24: =_xlfn.LET( _xlpm.qty, C24, _xlpm.hours, J24*24, _xlpm.price, _xlfn.XLOOKUP(TRIM(D24), Settings!$F$4:$F$101, Settings!$H$4:$H$101, 0), _xlpm.life, _xlfn.XLOOKUP(TRIM(D24), Settings!$F$4:$F$101, Settings!$I$4:$I$101, 1), _xlpm.pct, _xlfn.XLOOKUP(TRIM(D24), Settings!$F$4:$F$101, Settings!$J$4:$J$101, 0), _xlpm.qty * _xlpm.hours * (_xlpm.price / _xlpm.life * _xlpm.pct) ) -> 313.33333 | Q24: =Jobs[[#This Row],[Post Pro/h]]*Settings!$D$18 -> 0 | R24: =(Jobs[[#This Row],[power/t]]+Jobs[[#This Row],[Matrial/t]]+Jobs[[#This Row],[downturn/t]]+Jobs[[#This Row],[Maintenance/t]]+Jobs[[#This Row],[Coloring/t]]+Jobs[[#This Row],[Extras]])*Settings!$D$12 -> 3621.744 | S24: =Jobs[[#This Row],[Matrial/t]] + Jobs[[#This Row],[power/t]] + Jobs[[#This Row],[downturn/t]] + Jobs[[#This Row],[Maintenance/t]] + Jobs[[#This Row],[Coloring/t]] + Jobs[[#This Row],[overhead/t]] + Jobs[[#This Row],[Extras]] -> 15694.224 | T24: =S24*(1+Settings!$D$5) -> 47082.672 | U24: =Jobs[[#This Row],[Sugested Price/t]] - Jobs[[#This Row],[base price/t]] -> 31388.448 | V24: =IFERROR(Jobs[[#This Row],[Gross margin/t]] / Jobs[[#This Row],[base price/t]], 0) -> 2
B25: گوشواره ایر جردن | C25: 1 | D25: Anycubic Kobra S1- office | E25: PLA | F25: Black | G25: 15 | J25: 0.03125 | M25: =_xlfn.LET( _xlpm.qty, C25, _xlpm.weight_g, G25 + H25 + Jobs[[#This Row],[Flushed/g]], _xlpm.material, TRIM(E25), _xlpm.price_per_kg, _xlfn.XLOOKUP(_xlpm.material, MaterialsTbl[Material], MaterialsTbl[Price_per_kg], 0), _xlpm.waste_pct, _xlfn.XLOOKUP(_xlpm.material, MaterialsTbl[Material], MaterialsTbl[Waste_pct], 0), _xlpm.qty * (_xlpm.weight_g / 1000) * _xlpm.price_per_kg * (1 + _xlpm.waste_pct) ) -> 40950 | N25: =_xlfn.LET( _xlpm.qty, C25, _xlpm.hours, J25*24, _xlpm.power_w, _xlfn.XLOOKUP(TRIM(D25), Settings!$F$4:$F$101, Settings!$G$4:$G$101, 120), _xlpm.rate, Settings!$D$4, _xlpm.qty * _xlpm.hours * (_xlpm.power_w / 1000) * _xlpm.rate ) -> 73.08 | O25: =_xlfn.LET( _xlpm.qty, C25, _xlpm.hours, J25*24, _xlpm.price, _xlfn.XLOOKUP(TRIM(D25), Settings!$F$4:$F$101, Settings!$H$4:$H$101, 0), _xlpm.life, _xlfn.XLOOKUP(TRIM(D25), Settings!$F$4:$F$101, Settings!$I$4:$I$101, 1), _xlpm.qty * _xlpm.hours * (_xlpm.price / _xlpm.life) ) -> 14100 | P25: =_xlfn.LET( _xlpm.qty, C25, _xlpm.hours, J25*24, _xlpm.price, _xlfn.XLOOKUP(TRIM(D25), Settings!$F$4:$F$101, Settings!$H$4:$H$101, 0), _xlpm.life, _xlfn.XLOOKUP(TRIM(D25), Settings!$F$4:$F$101, Settings!$I$4:$I$101, 1), _xlpm.pct, _xlfn.XLOOKUP(TRIM(D25), Settings!$F$4:$F$101, Settings!$J$4:$J$101, 0), _xlpm.qty * _xlpm.hours * (_xlpm.price / _xlpm.life * _xlpm.pct) ) -> 705 | Q25: =Jobs[[#This Row],[Post Pro/h]]*Settings!$D$18 -> 0 | R25: =(Jobs[[#This Row],[power/t]]+Jobs[[#This Row],[Matrial/t]]+Jobs[[#This Row],[downturn/t]]+Jobs[[#This Row],[Maintenance/t]]+Jobs[[#This Row],[Coloring/t]]+Jobs[[#This Row],[Extras]])*Settings!$D$12 -> 16748.424 | S25: =Jobs[[#This Row],[Matrial/t]] + Jobs[[#This Row],[power/t]] + Jobs[[#This Row],[downturn/t]] + Jobs[[#This Row],[Maintenance/t]] + Jobs[[#This Row],[Coloring/t]] + Jobs[[#This Row],[overhead/t]] + Jobs[[#This Row],[Extras]] -> 72576.504 | T25: =S25*(1+Settings!$D$5) -> 217729.51 | U25: =Jobs[[#This Row],[Sugested Price/t]] - Jobs[[#This Row],[base price/t]] -> 145153.01 | V25: =IFERROR(Jobs[[#This Row],[Gross margin/t]] / Jobs[[#This Row],[base price/t]], 0) -> 2
B26: مار فلکسی | C26: 1 | D26: Anycubic Kobra S1- office | E26: PLA | F26: Olive Green | G26: 3 | J26: 0.015277778 | M26: =_xlfn.LET( _xlpm.qty, C26, _xlpm.weight_g, G26 + H26 + Jobs[[#This Row],[Flushed/g]], _xlpm.material, TRIM(E26), _xlpm.price_per_kg, _xlfn.XLOOKUP(_xlpm.material, MaterialsTbl[Material], MaterialsTbl[Price_per_kg], 0), _xlpm.waste_pct, _xlfn.XLOOKUP(_xlpm.material, MaterialsTbl[Material], MaterialsTbl[Waste_pct], 0), _xlpm.qty * (_xlpm.weight_g / 1000) * _xlpm.price_per_kg * (1 + _xlpm.waste_pct) ) -> 8190 | N26: =_xlfn.LET( _xlpm.qty, C26, _xlpm.hours, J26*24, _xlpm.power_w, _xlfn.XLOOKUP(TRIM(D26), Settings!$F$4:$F$101, Settings!$G$4:$G$101, 120), _xlpm.rate, Settings!$D$4, _xlpm.qty * _xlpm.hours * (_xlpm.power_w / 1000) * _xlpm.rate ) -> 35.728 | O26: =_xlfn.LET( _xlpm.qty, C26, _xlpm.hours, J26*24, _xlpm.price, _xlfn.XLOOKUP(TRIM(D26), Settings!$F$4:$F$101, Settings!$H$4:$H$101, 0), _xlpm.life, _xlfn.XLOOKUP(TRIM(D26), Settings!$F$4:$F$101, Settings!$I$4:$I$101, 1), _xlpm.qty * _xlpm.hours * (_xlpm.price / _xlpm.life) ) -> 6893.3333 | P26: =_xlfn.LET( _xlpm.qty, C26, _xlpm.hours, J26*24, _xlpm.price, _xlfn.XLOOKUP(TRIM(D26), Settings!$F$4:$F$101, Settings!$H$4:$H$101, 0), _xlpm.life, _xlfn.XLOOKUP(TRIM(D26), Settings!$F$4:$F$101, Settings!$I$4:$I$101, 1), _xlpm.pct, _xlfn.XLOOKUP(TRIM(D26), Settings!$F$4:$F$101, Settings!$J$4:$J$101, 0), _xlpm.qty * _xlpm.hours * (_xlpm.price / _xlpm.life * _xlpm.pct) ) -> 344.66667 | Q26: =Jobs[[#This Row],[Post Pro/h]]*Settings!$D$18 -> 0 | R26: =(Jobs[[#This Row],[power/t]]+Jobs[[#This Row],[Matrial/t]]+Jobs[[#This Row],[downturn/t]]+Jobs[[#This Row],[Maintenance/t]]+Jobs[[#This Row],[Coloring/t]]+Jobs[[#This Row],[Extras]])*Settings!$D$12 -> 4639.1184 | S26: =Jobs[[#This Row],[Matrial/t]] + Jobs[[#This Row],[power/t]] + Jobs[[#This Row],[downturn/t]] + Jobs[[#This Row],[Maintenance/t]] + Jobs[[#This Row],[Coloring/t]] + Jobs[[#This Row],[overhead/t]] + Jobs[[#This Row],[Extras]] -> 20102.846 | T26: =S26*(1+Settings!$D$5) -> 60308.539 | U26: =Jobs[[#This Row],[Sugested Price/t]] - Jobs[[#This Row],[base price/t]] -> 40205.693 | V26: =IFERROR(Jobs[[#This Row],[Gross margin/t]] / Jobs[[#This Row],[base price/t]], 0) -> 2
B27: مارملوک فلکسی | C27: 1 | D27: Anycubic Kobra S1- office | E27: PLA | F27: Olive Green | G27: 5 | J27: 0.020833333 | M27: =_xlfn.LET( _xlpm.qty, C27, _xlpm.weight_g, G27 + H27 + Jobs[[#This Row],[Flushed/g]], _xlpm.material, TRIM(E27), _xlpm.price_per_kg, _xlfn.XLOOKUP(_xlpm.material, MaterialsTbl[Material], MaterialsTbl[Price_per_kg], 0), _xlpm.waste_pct, _xlfn.XLOOKUP(_xlpm.material, MaterialsTbl[Material], MaterialsTbl[Waste_pct], 0), _xlpm.qty * (_xlpm.weight_g / 1000) * _xlpm.price_per_kg * (1 + _xlpm.waste_pct) ) -> 13650 | N27: =_xlfn.LET( _xlpm.qty, C27, _xlpm.hours, J27*24, _xlpm.power_w, _xlfn.XLOOKUP(TRIM(D27), Settings!$F$4:$F$101, Settings!$G$4:$G$101, 120), _xlpm.rate, Settings!$D$4, _xlpm.qty * _xlpm.hours * (_xlpm.power_w / 1000) * _xlpm.rate ) -> 48.72 | O27: =_xlfn.LET( _xlpm.qty, C27, _xlpm.hours, J27*24, _xlpm.price, _xlfn.XLOOKUP(TRIM(D27), Settings!$F$4:$F$101, Settings!$H$4:$H$101, 0), _xlpm.life, _xlfn.XLOOKUP(TRIM(D27), Settings!$F$4:$F$101, Settings!$I$4:$I$101, 1), _xlpm.qty * _xlpm.hours * (_xlpm.price / _xlpm.life) ) -> 9400 | P27: =_xlfn.LET( _xlpm.qty, C27, _xlpm.hours, J27*24, _xlpm.price, _xlfn.XLOOKUP(TRIM(D27), Settings!$F$4:$F$101, Settings!$H$4:$H$101, 0), _xlpm.life, _xlfn.XLOOKUP(TRIM(D27), Settings!$F$4:$F$101, Settings!$I$4:$I$101, 1), _xlpm.pct, _xlfn.XLOOKUP(TRIM(D27), Settings!$F$4:$F$101, Settings!$J$4:$J$101, 0), _xlpm.qty * _xlpm.hours * (_xlpm.price / _xlpm.life * _xlpm.pct) ) -> 470 | Q27: =Jobs[[#This Row],[Post Pro/h]]*Settings!$D$18 -> 0 | R27: =(Jobs[[#This Row],[power/t]]+Jobs[[#This Row],[Matrial/t]]+Jobs[[#This Row],[downturn/t]]+Jobs[[#This Row],[Maintenance/t]]+Jobs[[#This Row],[Coloring/t]]+Jobs[[#This Row],[Extras]])*Settings!$D$12 -> 7070.616 | S27: =Jobs[[#This Row],[Matrial/t]] + Jobs[[#This Row],[power/t]] + Jobs[[#This Row],[downturn/t]] + Jobs[[#This Row],[Maintenance/t]] + Jobs[[#This Row],[Coloring/t]] + Jobs[[#This Row],[overhead/t]] + Jobs[[#This Row],[Extras]] -> 30639.336 | T27: =S27*(1+Settings!$D$5) -> 91918.008 | U27: =Jobs[[#This Row],[Sugested Price/t]] - Jobs[[#This Row],[base price/t]] -> 61278.672 | V27: =IFERROR(Jobs[[#This Row],[Gross margin/t]] / Jobs[[#This Row],[base price/t]], 0) -> 2
